[2024-07-02T01:40:16.263+0300] {local_task_job_runner.py:120} INFO - ::group::Pre task execution logs
[2024-07-02T01:40:16.380+0300] {taskinstance.py:2076} INFO - Dependencies all met for dep_context=non-requeueable deps ti=<TaskInstance: weather_data_pipeline.fetch_weather_data scheduled__2024-07-01T12:00:00+00:00 [queued]>
[2024-07-02T01:40:16.387+0300] {taskinstance.py:2076} INFO - Dependencies all met for dep_context=requeueable deps ti=<TaskInstance: weather_data_pipeline.fetch_weather_data scheduled__2024-07-01T12:00:00+00:00 [queued]>
[2024-07-02T01:40:16.399+0300] {taskinstance.py:2306} INFO - Starting attempt 1 of 2
[2024-07-02T01:40:16.414+0300] {taskinstance.py:2330} INFO - Executing <Task(PythonOperator): fetch_weather_data> on 2024-07-01 12:00:00+00:00
[2024-07-02T01:40:16.440+0300] {standard_task_runner.py:63} INFO - Started process 10224 to run task
[2024-07-02T01:40:16.448+0300] {standard_task_runner.py:90} INFO - Running: ['airflow', 'tasks', 'run', 'weather_data_pipeline', 'fetch_weather_data', 'scheduled__2024-07-01T12:00:00+00:00', '--job-id', '366', '--raw', '--subdir', 'DAGS_FOLDER/Fetch_ingest_DAG.py', '--cfg-path', '/tmp/tmp9w09vrsg']
[2024-07-02T01:40:16.452+0300] {standard_task_runner.py:91} INFO - Job 366: Subtask fetch_weather_data
[2024-07-02T01:40:16.503+0300] {task_command.py:426} INFO - Running <TaskInstance: weather_data_pipeline.fetch_weather_data scheduled__2024-07-01T12:00:00+00:00 [running]> on host DESKTOP-1R67MDQ.
[2024-07-02T01:40:16.605+0300] {taskinstance.py:2648} INFO - Exporting env vars: AIRFLOW_CTX_DAG_OWNER='airflow' AIRFLOW_CTX_DAG_ID='weather_data_pipeline' AIRFLOW_CTX_TASK_ID='fetch_weather_data' AIRFLOW_CTX_EXECUTION_DATE='2024-07-01T12:00:00+00:00' AIRFLOW_CTX_TRY_NUMBER='1' AIRFLOW_CTX_DAG_RUN_ID='scheduled__2024-07-01T12:00:00+00:00'
[2024-07-02T01:40:16.607+0300] {taskinstance.py:430} INFO - ::endgroup::
[2024-07-03T12:31:33.531+0300] {taskinstance.py:441} INFO - ::group::Post task execution logs
[2024-07-03T12:31:33.532+0300] {taskinstance.py:2905} ERROR - Task failed with exception
Traceback (most recent call last):
  File "/home/user/rubix/internship_project/.venv/lib/python3.10/site-packages/urllib3/connection.py", line 198, in _new_conn
    sock = connection.create_connection(
  File "/home/user/rubix/internship_project/.venv/lib/python3.10/site-packages/urllib3/util/connection.py", line 60, in create_connection
    for res in socket.getaddrinfo(host, port, family, socket.SOCK_STREAM):
  File "/usr/lib/python3.10/socket.py", line 955, in getaddrinfo
    for res in _socket.getaddrinfo(host, port, family, type, proto, flags):
socket.gaierror: [Errno -3] Temporary failure in name resolution

The above exception was the direct cause of the following exception:

Traceback (most recent call last):
  File "/home/user/rubix/internship_project/.venv/lib/python3.10/site-packages/urllib3/connectionpool.py", line 793, in urlopen
    response = self._make_request(
  File "/home/user/rubix/internship_project/.venv/lib/python3.10/site-packages/urllib3/connectionpool.py", line 491, in _make_request
    raise new_e
  File "/home/user/rubix/internship_project/.venv/lib/python3.10/site-packages/urllib3/connectionpool.py", line 467, in _make_request
    self._validate_conn(conn)
  File "/home/user/rubix/internship_project/.venv/lib/python3.10/site-packages/urllib3/connectionpool.py", line 1099, in _validate_conn
    conn.connect()
  File "/home/user/rubix/internship_project/.venv/lib/python3.10/site-packages/urllib3/connection.py", line 616, in connect
    self.sock = sock = self._new_conn()
  File "/home/user/rubix/internship_project/.venv/lib/python3.10/site-packages/urllib3/connection.py", line 205, in _new_conn
    raise NameResolutionError(self.host, self, e) from e
urllib3.exceptions.NameResolutionError: <urllib3.connection.HTTPSConnection object at 0x7f47dabc7c70>: Failed to resolve 'api.openweathermap.org' ([Errno -3] Temporary failure in name resolution)

The above exception was the direct cause of the following exception:

Traceback (most recent call last):
  File "/home/user/rubix/internship_project/.venv/lib/python3.10/site-packages/requests/adapters.py", line 486, in send
    resp = conn.urlopen(
  File "/home/user/rubix/internship_project/.venv/lib/python3.10/site-packages/urllib3/connectionpool.py", line 847, in urlopen
    retries = retries.increment(
  File "/home/user/rubix/internship_project/.venv/lib/python3.10/site-packages/urllib3/util/retry.py", line 515, in increment
    raise MaxRetryError(_pool, url, reason) from reason  # type: ignore[arg-type]
urllib3.exceptions.MaxRetryError: HTTPSConnectionPool(host='api.openweathermap.org', port=443): Max retries exceeded with url: /data/2.5/weather?appid=a2b2e442aba806b89cc7e799526a1158&lon=35.5018&lat=33.8938 (Caused by NameResolutionError("<urllib3.connection.HTTPSConnection object at 0x7f47dabc7c70>: Failed to resolve 'api.openweathermap.org' ([Errno -3] Temporary failure in name resolution)"))

During handling of the above exception, another exception occurred:

Traceback (most recent call last):
  File "/home/user/rubix/internship_project/.venv/lib/python3.10/site-packages/airflow/models/taskinstance.py", line 465, in _execute_task
    result = _execute_callable(context=context, **execute_callable_kwargs)
  File "/home/user/rubix/internship_project/.venv/lib/python3.10/site-packages/airflow/models/taskinstance.py", line 432, in _execute_callable
    return execute_callable(context=context, **execute_callable_kwargs)
  File "/home/user/rubix/internship_project/.venv/lib/python3.10/site-packages/airflow/models/baseoperator.py", line 400, in wrapper
    return func(self, *args, **kwargs)
  File "/home/user/rubix/internship_project/.venv/lib/python3.10/site-packages/airflow/operators/python.py", line 235, in execute
    return_value = self.execute_callable()
  File "/home/user/rubix/internship_project/.venv/lib/python3.10/site-packages/airflow/operators/python.py", line 252, in execute_callable
    return self.python_callable(*self.op_args, **self.op_kwargs)
  File "/home/user/rubix/internship_project/dags/Fetch_ingest_DAG.py", line 32, in fetch_weather_data
    response = requests.get(url)
  File "/home/user/rubix/internship_project/.venv/lib/python3.10/site-packages/requests/api.py", line 73, in get
    return request("get", url, params=params, **kwargs)
  File "/home/user/rubix/internship_project/.venv/lib/python3.10/site-packages/requests/api.py", line 59, in request
    return session.request(method=method, url=url, **kwargs)
  File "/home/user/rubix/internship_project/.venv/lib/python3.10/site-packages/requests/sessions.py", line 589, in request
    resp = self.send(prep, **send_kwargs)
  File "/home/user/rubix/internship_project/.venv/lib/python3.10/site-packages/requests/sessions.py", line 703, in send
    r = adapter.send(request, **kwargs)
  File "/home/user/rubix/internship_project/.venv/lib/python3.10/site-packages/requests/adapters.py", line 519, in send
    raise ConnectionError(e, request=request)
requests.exceptions.ConnectionError: HTTPSConnectionPool(host='api.openweathermap.org', port=443): Max retries exceeded with url: /data/2.5/weather?appid=a2b2e442aba806b89cc7e799526a1158&lon=35.5018&lat=33.8938 (Caused by NameResolutionError("<urllib3.connection.HTTPSConnection object at 0x7f47dabc7c70>: Failed to resolve 'api.openweathermap.org' ([Errno -3] Temporary failure in name resolution)"))
[2024-07-03T12:31:33.700+0300] {taskinstance.py:1206} INFO - Marking task as UP_FOR_RETRY. dag_id=weather_data_pipeline, task_id=fetch_weather_data, run_id=scheduled__2024-07-01T12:00:00+00:00, execution_date=20240701T120000, start_date=20240701T224016, end_date=20240703T093133
[2024-07-03T12:31:33.810+0300] {standard_task_runner.py:110} ERROR - Failed to execute job 366 for task fetch_weather_data (HTTPSConnectionPool(host='api.openweathermap.org', port=443): Max retries exceeded with url: /data/2.5/weather?appid=a2b2e442aba806b89cc7e799526a1158&lon=35.5018&lat=33.8938 (Caused by NameResolutionError("<urllib3.connection.HTTPSConnection object at 0x7f47dabc7c70>: Failed to resolve 'api.openweathermap.org' ([Errno -3] Temporary failure in name resolution)")); 10224)
[2024-07-03T12:31:33.827+0300] {local_task_job_runner.py:240} INFO - Task exited with return code 1
[2024-07-03T12:31:33.902+0300] {taskinstance.py:3498} INFO - 0 downstream tasks scheduled from follow-on schedule check
[2024-07-03T12:31:33.903+0300] {local_task_job_runner.py:222} INFO - ::endgroup::
